<?xml version="1.0" encoding="utf-8"?>
<!-- This URDF was automatically created by SolidWorks to URDF Exporter! Originally created by Stephen Brawner (brawner@gmail.com) 
     Commit Version: 1.6.0-4-g7f85cfe  Build Version: 1.6.7995.38578
     For more information, please see http://wiki.ros.org/sw_urdf_exporter -->



<robot
  name="turtle">

  <!-- this is color -->
  <material name="black">
    <color rgba="0.0 0.0 0.0 1.0"/>
  </material>
  <material name="blue">
    <color rgba="0.0 0.0 0.8 1.0"/>
  </material>
  <material name="green">
    <color rgba="0.0 0.8 0.0 1.0"/>
  </material>
  <material name="grey">
    <color rgba="0.2 0.2 0.2 1.0"/>
  </material>
  <material name="silver">
    <color rgba="0.913725490196 0.913725490196 0.847058823529 1.0"/>
  </material>
  <material name="orange">
    <color rgba="0.12 0.15 0.2 1.0"/>
  </material>
  <material name="brown">
    <color rgba="0.870588235294 0.811764705882 0.764705882353 1.0"/>
  </material>
  <material name="red">
    <color rgba="0.8 0.0 0.0 1.0"/>
  </material>
  <material name="white">
    <color rgba="1.0 1.0 1.0 1.0"/>
  </material>
  <material name="dark_grey">
  <color rgba="0.3 0.3 0.3 1.0"/>
  </material>
  <material name="sap_green">
  <color rgba="0.15 0.6 0.15 1.0"/>
  </material>


  <link
    name="base">
    <inertial>
      <origin
        xyz="0.0024702 -6.2361E-06 -3.2723E-05"
        rpy="0 0 0" />
      <mass
        value="3" />
      <inertia
        ixx="0.0064416"
        ixy="-6.598E-09"
        ixz="1.8225E-08"
        iyy="0.052309"
        iyz="9.1893E-11"
        izz="0.057306" />
    </inertial>
    <visual>
      <origin
        xyz="0 0 0"
        rpy="0 0 0" />
      <geometry>
        <mesh
          filename="../meshes/base.STL" />
      </geometry>
      <material
        name="dark_grey">
      </material>
    </visual>
    <collision>
      <origin
        xyz="0 0 -0.005"
        rpy="0 0 0" />
      <geometry>
        <box size="0.44 0.145 0.05"/> 
      </geometry>
    </collision>
  </link>
  <link
    name="fl_a">
    <inertial>
      <origin
        xyz="0.01675 -0.0069959 0.00042797"
        rpy="0 0 0" />
      <mass
        value="0.165" />
      <inertia
        ixx="4.0873E-05"
        ixy="-3.3502E-21"
        ixz="3.2234E-21"
        iyy="2.3822E-05"
        iyz="-5.3502E-07"
        izz="3.3476E-05" />
    </inertial>
    <visual>
      <origin
        xyz="0 0 0"
        rpy="0 0 0" />
      <geometry>
        <mesh
          filename="../meshes/fl_a.STL" />
      </geometry>
      <material
        name="dark_grey">
      </material>
    </visual>
  </link>
  <joint
    name="fl_a_joint"
    type="revolute">
    <origin
      xyz="0.1705 0.135 -0.0002"
      rpy="0 0 0" />
    <parent
      link="base" />
    <child
      link="fl_a" />
    <axis
      xyz="-1 0 0" />
    <limit
      lower="0"
      upper="1.5"
      effort="10"
      velocity="4" />
  </joint>
  <link
    name="fl_h">
    <inertial>
      <origin
        xyz="0.0069959 0.00042797 0.01675"
        rpy="0 0 0" />
      <mass
        value="0.165" />
      <inertia
        ixx="2.3822E-05"
        ixy="5.3502E-07"
        ixz="-3.0282E-21"
        iyy="3.3476E-05"
        iyz="-2.2349E-22"
        izz="4.0873E-05" />
    </inertial>
    <visual>
      <origin
        xyz="0 0 0"
        rpy="0 0 0" />
      <geometry>
        <mesh
          filename="../meshes/fl_h.STL" />
      </geometry>
      <material
        name="dark_grey">
      </material>
    </visual>
  </link>
  <joint
    name="fl_h_joint"
    type="revolute">
    <origin
      xyz="0.01675 0.007 0.0255"
      rpy="0 0 0" />
    <parent
      link="fl_a" />
    <child
      link="fl_h" />
    <axis
      xyz="0 0 -1" />
    <limit
      lower="-1.5"
      upper="1.5"
      effort="10"
      velocity="4" />
  </joint>
  <link
    name="fl_k">
    <inertial>
      <origin
        xyz="8.6793E-06 0.13841 6.2159E-05"
        rpy="0 0 0" />
      <mass
        value="0.4" />
      <inertia
        ixx="0.0057588"
        ixy="-7.8578E-07"
        ixz="3.4804E-07"
        iyy="0.0009461"
        iyz="-2.937E-06"
        izz="0.006184" />
    </inertial>
    <visual>
      <origin
        xyz="0 0 0"
        rpy="0 0 0" />
      <geometry>
        <mesh
          filename="../meshes/fl_k.STL" />
      </geometry>
      <material
        name="black">
      </material>
    </visual>
    <collision>
      <origin
        xyz="0 0.12 0"
        rpy="1.57 0 0" />
      <geometry>
        <cylinder length="0.23" radius="0.032"/>
      </geometry>
    </collision>
  </link>
  <joint
    name="fl_k_joint"
    type="fixed">
    <origin
      xyz="-0.007 0.0255 0.01675"
      rpy="0 0 0" />
    <parent
      link="fl_h" />
    <child
      link="fl_k" />
    <axis
      xyz="0 -1 0" />
    <limit
      lower="-2"
      upper="2"
      effort="10"
      velocity="4" />
  </joint>
  <link
    name="fl_foot">
    <inertial>
      <origin
        xyz="2.7756E-17 5.5511E-17 6.9389E-18"
        rpy="0 0 0" />
      <mass
        value="0.1" />
      <inertia
        ixx="5.6221E-05"
        ixy="0"
        ixz="0"
        iyy="5.6221E-05"
        iyz="0"
        izz="5.6221E-05" />
    </inertial>
    <visual>
      <origin
        xyz="0 0 0"
        rpy="0 0 0" />
      <geometry>
        <mesh
          filename="../meshes/fl_foot.STL" />
      </geometry>
      <material
        name="black">
      </material>
    </visual>
    <collision>
      <origin
        xyz="0 0 0"
        rpy="0 0 0" />
      <geometry>
        <sphere radius="0.032"/>
      </geometry>
    </collision>
  </link>
  <joint
    name="fl_foot_joint"
    type="fixed">
    <origin
      xyz="0 0.23 0"
      rpy="0 0 0" />
    <parent
      link="fl_k" />
    <child
      link="fl_foot" />
    <axis
      xyz="0 0 0" />
  </joint>
  <link
    name="rl_a">
    <inertial>
      <origin
        xyz="-0.01675 -0.00699589394401035 0.000427968094298376"
        rpy="0 0 0" />
      <mass
        value="0.165" />
      <inertia
        ixx="4.08729236803209E-05"
        ixy="-1.49401437984316E-21"
        ixz="1.55095654665266E-21"
        iyy="2.38220232449362E-05"
        iyz="-5.35019629935043E-07"
        izz="3.34756854541371E-05" />
    </inertial>
    <visual>
      <origin
        xyz="0 0 0"
        rpy="0 0 0" />
      <geometry>
        <mesh
          filename="../meshes/rl_a.STL" />
      </geometry>
      <material
        name="dark_grey">
      </material>
    </visual>
  </link>
  <joint
    name="rl_a_joint"
    type="revolute">
    <origin
      xyz="-0.1705 0.135 -0.0002"
      rpy="0 0 0" />
    <parent
      link="base" />
    <child
      link="rl_a" />
    <axis
      xyz="1 0 0" />
    <limit
      lower="-1.5"
      upper="0"
      effort="10"
      velocity="4" />
  </joint>
  <link
    name="rl_h">
    <inertial>
      <origin
        xyz="-0.00699589394401037 0.000427968094298348 0.01675"
        rpy="0 0 0" />
      <mass
        value="0.165" />
      <inertia
        ixx="2.38220232449363E-05"
        ixy="-5.35019629935042E-07"
        ixz="3.17315910633076E-21"
        iyy="3.34756854541372E-05"
        iyz="-3.46763216190758E-22"
        izz="4.0872923680321E-05" />
    </inertial>
    <visual>
      <origin
        xyz="0 0 0"
        rpy="0 0 0" />
      <geometry>
        <mesh
          filename="../meshes/rl_h.STL" />
      </geometry>
      <material
        name="dark_grey">
      </material>
    </visual>
  </link>
  <joint
    name="rl_h_joint"
    type="revolute">
    <origin
      xyz="-0.01675 0.007 0.0255"
      rpy="0 0 0" />
    <parent
      link="rl_a" />
    <child
      link="rl_h" />
    <axis
      xyz="0 0 -1" />
    <limit
      lower="-1.5"
      upper="1.5"
      effort="10"
      velocity="4" />
  </joint>
  <link
    name="rl_k">
    <inertial>
      <origin
        xyz="8.6792881373865E-06 0.138409311171822 6.21593601340051E-05"
        rpy="0 0 0" />
      <mass
        value="0.4" />
      <inertia
        ixx="0.0057587524819182"
        ixy="-7.85775183115975E-07"
        ixz="3.480397512584E-07"
        iyy="0.000946104213487953"
        iyz="-2.93699510094559E-06"
        izz="0.00618404285776681" />
    </inertial>
    <visual>
      <origin
        xyz="0 0 0"
        rpy="0 0 0" />
      <geometry>
        <mesh
          filename="../meshes/rl_k.STL" />
      </geometry>
      <material
        name="black">
      </material>
    </visual>
    <collision>
      <origin
        xyz="0 0.12 0"
        rpy="1.57 0 0" />
      <geometry>
        <cylinder length="0.23" radius="0.032"/>
      </geometry>
    </collision>
  </link>
  <joint
    name="rl_k_joint"
    type="fixed">
    <origin
      xyz="0.007 0.0255 0.01675"
      rpy="0 0 0" />
    <parent
      link="rl_h" />
    <child
      link="rl_k" />
    <axis
      xyz="0 -1 0" />
    <limit
      lower="0"
      upper="0"
      effort="0"
      velocity="0" />
  </joint>
  <link
    name="rl_foot">
    <inertial>
      <origin
        xyz="-2.77555756156289E-17 5.55111512312578E-17 6.93889390390723E-18"
        rpy="0 0 0" />
      <mass
        value="0.1" />
      <inertia
        ixx="5.62209904355084E-05"
        ixy="0"
        ixz="0"
        iyy="5.62209904355084E-05"
        iyz="0"
        izz="5.62209904355084E-05" />
    </inertial>
    <visual>
      <origin
        xyz="0 0 0"
        rpy="0 0 0" />
      <geometry>
        <mesh
          filename="../meshes/rl_foot.STL" />
      </geometry>
      <material
        name="black">
      </material>
    </visual>
    <collision>
      <origin
        xyz="0 0 0"
        rpy="0 0 0" />
      <geometry>
        <sphere radius="0.032"/>
      </geometry>
    </collision>
  </link>
  <joint
    name="rl_foot_joint"
    type="fixed">
    <origin
      xyz="0 0.23 0"
      rpy="0 0 0" />
    <parent
      link="rl_k" />
    <child
      link="rl_foot" />
    <axis
      xyz="0 0 0" />
  </joint>
  <link
    name="rr_a">
    <inertial>
      <origin
        xyz="-0.0167500000000001 0.00699589394401037 0.000427968094298359"
        rpy="0 0 0" />
      <mass
        value="0.165" />
      <inertia
        ixx="4.08729236803209E-05"
        ixy="-3.90862116269727E-21"
        ixz="-2.9196488041723E-21"
        iyy="2.38220232449362E-05"
        iyz="5.35019629935046E-07"
        izz="3.34756854541371E-05" />
    </inertial>
    <visual>
      <origin
        xyz="0 0 0"
        rpy="0 0 0" />
      <geometry>
        <mesh
          filename="../meshes/rr_a.STL" />
      </geometry>
      <material
        name="dark_grey">
      </material>
    </visual>
  </link>
  <joint
    name="rr_a_joint"
    type="revolute">
    <origin
      xyz="-0.1705 -0.135 -0.0002"
      rpy="0 0 0" />
    <parent
      link="base" />
    <child
      link="rr_a" />
    <axis
      xyz="1 0 0" />
    <limit
      lower="0"
      upper="1.5"
      effort="10"
      velocity="4" />
  </joint>
  <link
    name="rr_h">
    <inertial>
      <origin
        xyz="-0.00699589394401035 -0.000427968094298375 0.01675"
        rpy="0 0 0" />
      <mass
        value="0.165" />
      <inertia
        ixx="2.38220232449362E-05"
        ixy="5.35019629935048E-07"
        ixz="-6.53477871912388E-22"
        iyy="3.34756854541372E-05"
        iyz="3.57775258725746E-22"
        izz="4.0872923680321E-05" />
    </inertial>
    <visual>
      <origin
        xyz="0 0 0"
        rpy="0 0 0" />
      <geometry>
        <mesh
          filename="../meshes/rr_h.STL" />
      </geometry>
      <material
        name="dark_grey">
      </material>
    </visual>
  </link>
  <joint
    name="rr_h_joint"
    type="revolute">
    <origin
      xyz="-0.01675 -0.007 0.0255"
      rpy="0 0 0" />
    <parent
      link="rr_a" />
    <child
      link="rr_h" />
    <axis
      xyz="0 0 -1" />
    <limit
      lower="-1.5"
      upper="1.5"
      effort="10"
      velocity="4" />
  </joint>
  <link
    name="rr_k">
    <inertial>
      <origin
        xyz="-8.67928813735874E-06 -0.138409311171821 6.2159360134019E-05"
        rpy="0 0 0" />
      <mass
        value="0.4" />
      <inertia
        ixx="0.00575875248191818"
        ixy="-7.85775183111665E-07"
        ixz="-3.48039751257821E-07"
        iyy="0.000946104213487952"
        iyz="2.93699510094755E-06"
        izz="0.00618404285776679" />
    </inertial>
    <visual>
      <origin
        xyz="0 0 0"
        rpy="0 0 0" />
      <geometry>
        <mesh
          filename="../meshes/rr_k.STL" />
      </geometry>
      <material
        name="black">
      </material>
    </visual>
    <collision>
      <origin
        xyz="0 -0.12 0"
        rpy="1.57 0 0" />
      <geometry>
        <cylinder length="0.23" radius="0.032"/>
      </geometry>
    </collision>
  </link>
  <joint
    name="rr_k_joint"
    type="fixed">
    <origin
      xyz="0.007 -0.0255 0.01675"
      rpy="0 0 0" />
    <parent
      link="rr_h" />
    <child
      link="rr_k" />
    <axis
      xyz="0 1 0" />
    <limit
      lower="0"
      upper="0"
      effort="0"
      velocity="0" />
  </joint>
  <link
    name="rr_foot">
    <inertial>
      <origin
        xyz="0 5.55111512312578E-17 6.93889390390723E-18"
        rpy="0 0 0" />
      <mass
        value="0.1" />
      <inertia
        ixx="5.62209904355084E-05"
        ixy="8.35238971903811E-53"
        ixz="0"
        iyy="5.62209904355084E-05"
        iyz="0"
        izz="5.62209904355084E-05" />
    </inertial>
    <visual>
      <origin
        xyz="0 0 0"
        rpy="0 0 0" />
      <geometry>
        <mesh
          filename="../meshes/rr_foot.STL" />
      </geometry>
      <material
        name="black">
      </material>
    </visual>
    <collision>
      <origin
        xyz="0 0 0"
        rpy="0 0 0" />
      <geometry>
        <sphere radius="0.032"/>
      </geometry>
    </collision>
  </link>
  <joint
    name="rr_foot_joint"
    type="fixed">
    <origin
      xyz="0 -0.23 0"
      rpy="0 0 0" />
    <parent
      link="rr_k" />
    <child
      link="rr_foot" />
    <axis
      xyz="0 0 0" />
  </joint>
  <link
    name="fr_a">
    <inertial>
      <origin
        xyz="0 0 0"
        rpy="0 0 0" />
      <mass
        value="0.165" />
      <inertia
        ixx="0"
        ixy="0"
        ixz="0"
        iyy="0"
        iyz="0"
        izz="0" />
    </inertial>
    <visual>
      <origin
        xyz="0 0 0"
        rpy="0 0 0" />
      <geometry>
        <mesh
          filename="../meshes/fr_a.STL" />
      </geometry>
      <material
        name="dark_grey">
      </material>
    </visual>
  </link>
  <joint
    name="fr_a_joint"
    type="revolute">
    <origin
      xyz="0.1705 -0.135 -0.0002"
      rpy="0 0 0" />
    <parent
      link="base" />
    <child
      link="fr_a" />
    <axis
      xyz="-1 0 0" />
    <limit
      lower="-1.5"
      upper="0"
      effort="10"
      velocity="4" />
  </joint>
  <link
    name="fr_h">
    <inertial>
      <origin
        xyz="0.00699589394401046 -0.000427968094298431 0.01675"
        rpy="0 0 0" />
      <mass
        value="0.165" />
      <inertia
        ixx="2.38220232449362E-05"
        ixy="-5.35019629935039E-07"
        ixz="1.09033306488563E-21"
        iyy="3.34756854541371E-05"
        iyz="-1.08280922162738E-21"
        izz="4.08729236803209E-05" />
    </inertial>
    <visual>
      <origin
        xyz="0 0 0"
        rpy="0 0 0" />
      <geometry>
        <mesh
          filename="../meshes/fr_h.STL" />
      </geometry>
      <material
        name="dark_grey">
      </material>
    </visual>
  </link>
  <joint
    name="fr_h_joint"
    type="revolute">
    <origin
      xyz="0.01675 -0.007 0.0255"
      rpy="0 0 0" />
    <parent
      link="fr_a" />
    <child
      link="fr_h" />
    <axis
      xyz="0 0 -1" />
    <limit
      lower="-1.5"
      upper="1.5"
      effort="10"
      velocity="4" />
  </joint>
  <link
    name="fr_k">
    <inertial>
      <origin
        xyz="-8.67928813755303E-06 -0.138409311171822 6.2159360134012E-05"
        rpy="0 0 0" />
      <mass
        value="0.4" />
      <inertia
        ixx="0.00575875248191825"
        ixy="-7.85775183127066E-07"
        ixz="-3.48039751258716E-07"
        iyy="0.000946104213487957"
        iyz="2.93699510094476E-06"
        izz="0.00618404285776686" />
    </inertial>
    <visual>
      <origin
        xyz="0 0 0"
        rpy="0 0 0" />
      <geometry>
        <mesh
          filename="../meshes/fr_k.STL" />
      </geometry>
      <material
        name="black">
      </material>
    </visual>
    <collision>
      <origin
        xyz="0 -0.12 0"
        rpy="1.57 0 0" />
      <geometry>
        <cylinder length="0.23" radius="0.032"/>
      </geometry>
    </collision>
  </link>
  <joint
    name="fr_k_joint"
    type="fixed">
    <origin
      xyz="-0.007 -0.0255 0.01675"
      rpy="0 0 0" />
    <parent
      link="fr_h" />
    <child
      link="fr_k" />
    <axis
      xyz="0 1 0" />
    <limit
      lower="0"
      upper="0"
      effort="0"
      velocity="0" />
  </joint>
  <link
    name="fr_foot">
    <inertial>
      <origin
        xyz="1.38777878078145E-16 5.55111512312578E-17 -6.03683769639929E-16"
        rpy="0 0 0" />
      <mass
        value="0.1" />
      <inertia
        ixx="5.62209904355085E-05"
        ixy="1.21972744404619E-20"
        ixz="5.42101086242758E-21"
        iyy="5.62209904355084E-05"
        iyz="2.71050543121379E-21"
        izz="5.62209904355084E-05" />
    </inertial>
    <visual>
      <origin
        xyz="0 0 0"
        rpy="0 0 0" />
      <geometry>
        <mesh
          filename="../meshes/fr_foot.STL" />
      </geometry>
      <material
        name="black">
      </material>
    </visual>
    <collision>
      <origin
        xyz="0 0 0"
        rpy="0 0 0" />
      <geometry>
        <sphere radius="0.032"/>
      </geometry>
    </collision>
  </link>
  <joint
    name="fr_foot_joint"
    type="fixed">
    <origin
      xyz="0 -0.23 0"
      rpy="0 0 0" />
    <parent
      link="fr_k" />
    <child
      link="fr_foot" />
    <axis
      xyz="0 0 0" />
  </joint>
  <link
    name="chassis">
    <inertial>
      <origin
        xyz="-0.0147501998320291 -3.53417656437014E-05 0.0184509410066664"
        rpy="0 0 0" />
      <mass
        value="0.0" />
      <inertia
        ixx="0.0050986512131768"
        ixy="4.37512838929446E-07"
        ixz="-0.00020818844644058"
        iyy="0.0112238910306416"
        iyz="1.24889532652392E-07"
        izz="0.0157805538355785" />
    </inertial>
    <visual>
      <origin
        xyz="0 0 0"
        rpy="0 0 0" />
      <geometry>
        <mesh
          filename="../meshes/chassis.STL" />
      </geometry>
      <material
        name="sap_green">
      </material>
    </visual>
  </link>
  <joint
    name="chassis_fixed"
    type="fixed">
    <origin
      xyz="0 0 0"
      rpy="0 0 0" />
    <parent
      link="base" />
    <child
      link="chassis" />
    <axis
      xyz="0 0 0" />
  </joint>
</robot>